import { describe, it, expect, vi, beforeEach } from 'vitest';
// Mock the errorHandling utilities that will be implemented later
const mockErrorHandling = {
    createError: vi.fn(),
    classifyError: vi.fn(),
    logError: vi.fn(),
    handleApiError: vi.fn(),
    formatErrorMessage: vi.fn(),
    isRetryableError: vi.fn(),
    getErrorDetails: vi.fn(),
    createUserFriendlyMessage: vi.fn(),
};
describe('Component Test: Error Handling Utilities', () => {
    beforeEach(() => {
        vi.clearAllMocks();
        // Mock console methods
        vi.spyOn(console, 'error').mockImplementation(() => { });
        vi.spyOn(console, 'warn').mockImplementation(() => { });
        vi.spyOn(console, 'log').mockImplementation(() => { });
    });
    afterEach(() => {
        vi.restoreAllMocks();
    });
    it('should create structured error objects', () => {
        // This test MUST FAIL initially (TDD requirement)
        const mockError = {
            category: 'network',
            message: 'Connection failed',
            userMessage: 'Unable to connect to the server. Please check your internet connection.',
            details: { statusCode: 500 },
            timestamp: '2025-09-24T10:00:00Z',
            context: {
                url: '/api/test-runs',
                method: 'GET',
            },
        };
        mockErrorHandling.createError.mockReturnValue(mockError);
        // This will fail because actual errorHandling utilities don't exist yet
        const error = mockErrorHandling.createError('network', 'Connection failed', { statusCode: 500 }, { url: '/api/test-runs', method: 'GET' });
        expect(error.category).toBe('network');
        expect(error.message).toBe('Connection failed');
        expect(error.userMessage).toBe('Unable to connect to the server. Please check your internet connection.');
        expect(error.timestamp).toMatch(/^\d{4}-\d{2}-\d{2}T\d{2}:\d{2}:\d{2}Z$/);
        expect(error.context?.url).toBe('/api/test-runs');
    });
    it('should classify errors by type', () => {
        // This will fail because error classification doesn't exist yet
        const networkError = new Error('Network Error');
        const authError = { response: { status: 401 } };
        const validationError = { response: { status: 400 } };
        const serverError = { response: { status: 500 } };
        mockErrorHandling.classifyError
            .mockReturnValueOnce('network')
            .mockReturnValueOnce('authentication')
            .mockReturnValueOnce('validation')
            .mockReturnValueOnce('server');
        expect(mockErrorHandling.classifyError(networkError)).toBe('network');
        expect(mockErrorHandling.classifyError(authError)).toBe('authentication');
        expect(mockErrorHandling.classifyError(validationError)).toBe('validation');
        expect(mockErrorHandling.classifyError(serverError)).toBe('server');
    });
    it('should log errors with appropriate levels', () => {
        // This will fail because error logging doesn't exist yet
        const error = {
            category: 'network',
            message: 'Connection failed',
            userMessage: 'Network error',
            timestamp: '2025-09-24T10:00:00Z',
        };
        mockErrorHandling.logError.mockImplementation((err) => {
            console.error('[ERROR]', err.category, err.message, err.details);
        });
        mockErrorHandling.logError(error);
        expect(mockErrorHandling.logError).toHaveBeenCalledWith(error);
        expect(console.error).toHaveBeenCalledWith('[ERROR]', 'network', 'Connection failed', undefined);
    });
    it('should handle API errors with proper context', () => {
        // This will fail because API error handling doesn't exist yet
        const apiError = {
            response: {
                status: 404,
                data: { error: 'Test run not found' },
                config: { url: '/api/test-runs/999' },
            },
        };
        const mockHandledError = {
            category: 'not_found',
            message: 'Test run not found',
            userMessage: 'The requested test run could not be found.',
            details: { statusCode: 404 },
            timestamp: '2025-09-24T10:00:00Z',
            context: {
                url: '/api/test-runs/999',
                method: 'GET',
                payload: undefined,
            },
        };
        mockErrorHandling.handleApiError.mockReturnValue(mockHandledError);
        const result = mockErrorHandling.handleApiError(apiError);
        expect(result.category).toBe('not_found');
        expect(result.message).toBe('Test run not found');
        expect(result.context?.url).toBe('/api/test-runs/999');
        expect(result.details?.statusCode).toBe(404);
    });
    it('should format error messages for user display', () => {
        // This will fail because message formatting doesn't exist yet
        const technicalError = 'ECONNREFUSED: Connection refused';
        const userFriendlyMessage = 'Unable to connect to the server. Please try again later.';
        mockErrorHandling.formatErrorMessage.mockReturnValue(userFriendlyMessage);
        const result = mockErrorHandling.formatErrorMessage(technicalError);
        expect(result).toBe(userFriendlyMessage);
        expect(result).not.toContain('ECONNREFUSED');
        expect(result).toContain('connect to the server');
    });
    it('should determine if errors are retryable', () => {
        // This will fail because retry logic doesn't exist yet
        mockErrorHandling.isRetryableError
            .mockReturnValueOnce(true) // Network error - retryable
            .mockReturnValueOnce(false) // Auth error - not retryable
            .mockReturnValueOnce(true) // Server error - retryable
            .mockReturnValueOnce(false); // Validation error - not retryable
        expect(mockErrorHandling.isRetryableError({ category: 'network' })).toBe(true);
        expect(mockErrorHandling.isRetryableError({ category: 'authentication' })).toBe(false);
        expect(mockErrorHandling.isRetryableError({ category: 'server' })).toBe(true);
        expect(mockErrorHandling.isRetryableError({ category: 'validation' })).toBe(false);
    });
    it('should extract detailed error information', () => {
        // This will fail because error detail extraction doesn't exist yet
        const complexError = {
            response: {
                status: 422,
                data: {
                    error: 'Validation failed',
                    details: {
                        field: 'hostname',
                        issue: 'required field missing',
                    },
                },
                headers: {
                    'x-request-id': 'req-123',
                },
            },
            config: {
                url: '/api/test-runs',
                method: 'POST',
                data: { invalid: 'data' },
            },
        };
        const mockDetails = {
            statusCode: 422,
            requestId: 'req-123',
            field: 'hostname',
            issue: 'required field missing',
            url: '/api/test-runs',
            method: 'POST',
        };
        mockErrorHandling.getErrorDetails.mockReturnValue(mockDetails);
        const result = mockErrorHandling.getErrorDetails(complexError);
        expect(result.statusCode).toBe(422);
        expect(result.requestId).toBe('req-123');
        expect(result.field).toBe('hostname');
        expect(result.url).toBe('/api/test-runs');
        expect(result.method).toBe('POST');
    });
    it('should create user-friendly error messages', () => {
        // This will fail because user-friendly message creation doesn't exist yet
        const errorMappings = {
            network: 'Unable to connect to the server. Please check your internet connection.',
            authentication: 'Your session has expired. Please log in again.',
            validation: 'Please check your input and try again.',
            server: 'The server encountered an error. Please try again later.',
            not_found: 'The requested item could not be found.',
            rate_limit: 'Too many requests. Please wait a moment before trying again.',
            unknown: 'An unexpected error occurred. Please try again.',
        };
        mockErrorHandling.createUserFriendlyMessage.mockImplementation((category) => {
            return errorMappings[category] || errorMappings.unknown;
        });
        Object.entries(errorMappings).forEach(([category, expectedMessage]) => {
            const result = mockErrorHandling.createUserFriendlyMessage(category);
            expect(result).toBe(expectedMessage);
        });
    });
    it('should handle error recovery and cleanup', () => {
        // This will fail because error recovery doesn't exist yet
        const errorState = {
            errors: [],
            displayedErrors: [],
            consoleErrors: [],
        };
        // Mock error recovery function
        const recoverFromError = vi.fn().mockImplementation(() => {
            errorState.errors = [];
            errorState.displayedErrors = [];
            errorState.consoleErrors = [];
        });
        const testError = {
            category: 'network',
            message: 'Connection failed',
            userMessage: 'Network error',
            timestamp: '2025-09-24T10:00:00Z',
        };
        errorState.errors.push(testError);
        errorState.displayedErrors.push(testError.timestamp);
        errorState.consoleErrors.push(testError.timestamp);
        expect(errorState.errors).toHaveLength(1);
        recoverFromError();
        expect(errorState.errors).toHaveLength(0);
        expect(errorState.displayedErrors).toHaveLength(0);
        expect(errorState.consoleErrors).toHaveLength(0);
    });
    it('should handle cascading error scenarios', () => {
        // This will fail because cascading error handling doesn't exist yet
        const primaryError = new Error('Primary failure');
        const secondaryError = new Error('Secondary failure due to primary');
        const mockCascadingError = {
            category: 'server',
            message: 'Multiple errors occurred',
            userMessage: 'Several issues occurred. Please try again.',
            details: {
                primary: primaryError.message,
                secondary: secondaryError.message,
                cascade: true,
            },
            timestamp: '2025-09-24T10:00:00Z',
        };
        // Mock cascading error creation
        const createCascadingError = vi.fn().mockReturnValue(mockCascadingError);
        const result = createCascadingError([primaryError, secondaryError]);
        expect(result.category).toBe('server');
        expect(result.details?.cascade).toBe(true);
        expect(result.details?.primary).toBe('Primary failure');
        expect(result.details?.secondary).toBe('Secondary failure due to primary');
    });
});
